Workbook
Name list4: '[1]list of incentive '!$E$3:$E$20

Sheet ASE Target (Spares), FY 21-22
B2: ='ASE Target vs Ach(Spares)(Inpt)'!C2 -> Month | C2: ='ASE Target vs Ach(Spares)(Inpt)'!D2 -> Jul | D2: ='ASE Target vs Ach(Spares)(Inpt)'!E2 -> <<< No input
A4: Sales | C4: Input if any new ASE appointed | G4: No input▼ | H4: input▼(if Require) | I4: input▼(if Require) | J4: input▼(if Require) | K4: input▼(if Require) | L4: input▼(if Require) | M4: input▼(if Require) | N4: input▼(if Require) | O4: input▼(if Require) | P4: input▼(if Require) | Q4: input▼(if Require) | R4: input▼(if Require) | S4: input▼(if Require)
A5: Sl. | B5: Wing | C5: Name | D5: ID | E5: Cell No | F5: Joinning Date | G5: Total Yearly Budget | H5: Jul | I5: Aug | J5: Sep | K5: Oct | L5: Nov | M5: Dec | N5: Jan | O5: Feb | P5: Mar | Q5: Apr | R5: May | S5: Jun
A6: 1 | B6: DSL-DHK | C6: Md. Shohidul | D6: 1418 | E6: `01730046583 | G6: =SUM(H6:S6) -> 2700000 | H6: 500000 | O6: 600000 | P6: 300000 | Q6: 400000 | R6: 400000 | S6: 500000
A7: 2 | B7: DSL-DHK | C7: Sagar Chakrobarti | D7: 2701 | E7: `01708911660 | G7: =SUM(H7:S7) -> 250000 | O7: 250000
A8: 3 | B8: DSL-DHK | C8: Md. Minhazul Islam | D8: 2330 | E8: `01762686570 | G8: =SUM(H8:S8) -> 2000000 | O8: 1000000 | P8: 1000000
A9: 4 | B9: DSL-DHK | C9: Md. Nazmul Hasan Titu | D9: 2913 | E9: `01730046581 | G9: =SUM(H9:S9) -> 1500000 | H9: 250000 | O9: 250000 | P9: 250000 | Q9: 250000 | R9: 250000 | S9: 250000
A10: 5 | B10: DSL-DHK | C10: Md. Zahirul Islam | D10: 2914 | E10: `01755520323 | G10: =SUM(H10:S10) -> 5600000 | H10: 1000000 | O10: 800000 | P10: 800000 | Q10: 1000000 | R10: 1000000 | S10: 1000000
A11: 6 | B11: DSL-DHK | C11: Md. Rakibul Hasan | D11: 2927 | E11: `01730046571 | G11: =SUM(H11:S11) -> 1900000 | H11: 300000 | O11: 400000 | P11: 300000 | Q11: 300000 | R11: 300000 | S11: 300000
A12: 7 | B12: DSL-DHK | C12: Md Ariful Islam | D12: 2699 | E12: `01708154106 | G12: =SUM(H12:S12) -> 2000000 | H12: 400000 | P12: 400000 | Q12: 400000 | R12: 400000 | S12: 400000
A13: 8 | B13: DSL-DHK | C13: Mohammad Jewel Rana | D13: 3002 | E13: `01762686572 | F13: 43893 | G13: =SUM(H13:S13) -> 3600000 | H13: 600000 | O13: 600000 | P13: 600000 | Q13: 600000 | R13: 600000 | S13: 600000
A14: 9 | B14: DSL-DHK | C14: Faysal Ahmed | D14: 3004 | E14: `01730046576 | F14: 43893 | G14: =SUM(H14:S14) -> 3600000 | H14: 600000 | O14: 600000 | P14: 600000 | Q14: 600000 | R14: 600000 | S14: 600000
A15: 10 | B15: DSL-DHK | C15: Rakibul Islam Razib | D15: 3006 | E15: `01730046580 | F15: 43893 | G15: =SUM(H15:S15) -> 1210000 | H15: 250000 | P15: 230000 | Q15: 230000 | R15: 250000 | S15: 250000
A16: 11 | B16: DSL-DHK | C16: Ashraful Islam | D16: 3003 | E16: `01764660814 | F16: 43898 | G16: =SUM(H16:S16) -> 3600000 | H16: 500000 | O16: 800000 | P16: 800000 | Q16: 500000 | R16: 500000 | S16: 500000
A17: 12 | B17: DSL-DHK | C17: Md. Rakibul Islam | D17: 5690 | E17: `01730046571 | F17: 44287 | G17: =SUM(H17:S17) -> 3600000 | H17: 600000 | O17: 600000 | P17: 600000 | Q17: 600000 | R17: 600000 | S17: 600000
A18: 13 | B18: DSL-DHK | C18: Ohid Hasan Saikat | D18: 5691 | E18: `01755520384 | F18: 44287 | G18: =SUM(H18:S18) -> 1900000 | H18: 300000 | O18: 300000 | P18: 400000 | Q18: 300000 | R18: 300000 | S18: 300000
A19: 14 | B19: DSL-DHK | C19: Abdullah Al Mahmud | D19: 5692 | E19: `01740053252 | F19: 44287 | G19: =SUM(H19:S19) -> 2700000 | H19: 400000 | O19: 700000 | P19: 400000 | Q19: 400000 | R19: 400000 | S19: 400000
A20: 15 | B20: DSL-DHK | C20: Apurba Kumar Gain | D20: 5927 | E20: `01730046577 | F20: 44565 | G20: =SUM(H20:S20) -> 1150000 | H20: 230000 | P20: 230000 | Q20: 230000 | R20: 230000 | S20: 230000
A21: 16 | B21: DSL-DHK | C21: Amirul Islam | D21: 5928 | F21: 44565 | G21: =SUM(H21:S21) -> 1250000 | H21: 250000 | O21: 0 | P21: 250000 | Q21: 250000 | R21: 250000 | S21: 250000
A22: 17 | B22: DSL-DHK | C22: Md. Jafor Ikbal | D22: 5929 | F22: 44565 | G22: =SUM(H22:S22) -> 0
A23: 14 | B23: DSL-DHK | C23: Md. Habibur Rahman | D23: 6079 | E23: `01740053252 | F23: 44287 | G23: =SUM(H23:S23) -> 500000 | H23: 250000 | S23: 250000
A24: 15 | B24: DSL-DHK | C24: Ashikur Rahman | D24: 6080 | E24: `01730046577 | F24: 44565 | G24: =SUM(H24:S24) -> 1000000 | H24: 500000 | S24: 500000
A25: 16 | B25: DSL-DHK | C25: Md. Sujon Hossain | D25: 6078 | F25: 44565 | G25: =SUM(H25:S25) -> 1200000 | H25: 600000 | S25: 600000
A26: 15 | B26: DSL-DHK | C26: Md Jiaur Rahman | D26: 0522 | E26: `01730046577 | F26: 44565 | G26: =SUM(H26:S26) -> 4350000 | H26: 900000 | P26: 850000 | Q26: 850000 | R26: 850000 | S26: 900000
A27: 16 | C27: New-2 | F27: 44565 | G27: =SUM(H27:S27) -> 0 | O27: 0
A28: 17 | C28: New-3 | F28: 44565 | G28: =SUM(H28:S28) -> 0
A29: 18 | C29: New-4 | E29: `01733050093 | G29: =SUM(H29:S29) -> 0
A30: 19 | B30: CTG | C30: Sumon Sen | D30: 8041 | G30: =SUM(H30:S30) -> 2250000 | O30: 450000 | P30: 450000 | Q30: 450000 | R30: 450000 | S30: 450000
A31: 20 | B31: CTG | C31: Tapan Barua | D31: 1475 | G31: =SUM(H31:S31) -> 2250000 | O31: 450000 | P31: 450000 | Q31: 450000 | R31: 450000 | S31: 450000
A32: 21 | B32: CTG | C32: Sozol prince | D32: 6076 | G32: =SUM(H32:S32) -> 2250000 | O32: 450000 | P32: 450000 | Q32: 450000 | R32: 450000 | S32: 450000
A33: 16 | C33: New-5 | F33: 44565 | G33: =SUM(H33:S33) -> 0 | O33: 0
A34: 17 | C34: New-6 | F34: 44565 | G34: =SUM(H34:S34) -> 0
H38: Collection Target = | J38: 0.5 | L38: 0.9 | M38: + | N38: 0.5 | P38: 0.9
A39: Collection Target | E39: of Sales | G39: =$G$4 -> No input▼ | H39: =$G$4 -> No input▼ | I39: =$G$4 -> No input▼ | J39: =$G$4 -> No input▼ | K39: =$G$4 -> No input▼ | L39: =$G$4 -> No input▼ | M39: =$G$4 -> No input▼ | N39: =$G$4 -> No input▼ | ... S39: =$G$4 -> No input▼
A40: Sl. | B40: Wing | C40: Name | D40: ID | E40: Cell No | F40: Joinning Date | G40: Total Yearly Budget | H40: Jul | I40: Aug | J40: Sep | K40: Oct | L40: Nov | M40: Dec | N40: Jan | O40: Feb | P40: Mar | Q40: Apr | R40: May | S40: Jun
A41: =A6 -> 1 | B41: =IF(B6=0,"",B6) -> DSL-DHK | C41: =IF(C6=0,"",C6) -> Md. Shohidul | D41: =IF(D6=0,"",D6) -> 1418 | E41: `01730046583 | G41: =SUM(H41:S41) -> 2205000 | H41: =$J$38*H6*$L$38 -> 225000 | I41: =$J$38*H6*$L$38+$N$38*I6*$P$38 -> 225000 | J41: =$J$38*I6*$L$38+$N$38*J6*$P$38 -> 0 | K41: =$J$38*J6*$L$38+$N$38*K6*$P$38 -> 0 | L41: =$J$38*K6*$L$38+$N$38*L6*$P$38 -> 0 | M41: =$J$38*L6*$L$38+$N$38*M6*$P$38 -> 0 | N41: =$J$38*M6*$L$38+$N$38*N6*$P$38 -> 0 | O41: =$J$38*N6*$L$38+$N$38*O6*$P$38 -> 270000 | P41: =$J$38*O6*$L$38+$N$38*P6*$P$38 -> 405000 | ... S41: =$J$38*R6*$L$38+$N$38*S6*$P$38 -> 405000
A42: =A7 -> 2 | B42: =IF(B7=0,"",B7) -> DSL-DHK | C42: =IF(C7=0,"",C7) -> Sagar Chakrobarti | D42: =IF(D7=0,"",D7) -> 2701 | E42: `01708911660 | G42: =SUM(H42:S42) -> 225000 | H42: =$J$38*H7*$L$38 -> 0 | I42: =$J$38*H7*$L$38+$N$38*I7*$P$38 -> 0 | J42: =$J$38*I7*$L$38+$N$38*J7*$P$38 -> 0 | K42: =$J$38*J7*$L$38+$N$38*K7*$P$38 -> 0 | L42: =$J$38*K7*$L$38+$N$38*L7*$P$38 -> 0 | M42: =$J$38*L7*$L$38+$N$38*M7*$P$38 -> 0 | N42: =$J$38*M7*$L$38+$N$38*N7*$P$38 -> 0 | O42: =$J$38*N7*$L$38+$N$38*O7*$P$38 -> 112500 | P42: =$J$38*O7*$L$38+$N$38*P7*$P$38 -> 112500 | ... S42: =$J$38*R7*$L$38+$N$38*S7*$P$38 -> 0
A43: =A8 -> 3 | B43: =IF(B8=0,"",B8) -> DSL-DHK | C43: =IF(C8=0,"",C8) -> Md. Minhazul Islam | D43: =IF(D8=0,"",D8) -> 2330 | E43: `01762686570 | G43: =SUM(H43:S43) -> 1800000 | H43: =$J$38*H8*$L$38 -> 0 | I43: =$J$38*H8*$L$38+$N$38*I8*$P$38 -> 0 | J43: =$J$38*I8*$L$38+$N$38*J8*$P$38 -> 0 | K43: =$J$38*J8*$L$38+$N$38*K8*$P$38 -> 0 | L43: =$J$38*K8*$L$38+$N$38*L8*$P$38 -> 0 | M43: =$J$38*L8*$L$38+$N$38*M8*$P$38 -> 0 | N43: =$J$38*M8*$L$38+$N$38*N8*$P$38 -> 0 | O43: =$J$38*N8*$L$38+$N$38*O8*$P$38 -> 450000 | P43: =$J$38*O8*$L$38+$N$38*P8*$P$38 -> 900000 | ... S43: =$J$38*R8*$L$38+$N$38*S8*$P$38 -> 0
A44: =A9 -> 4 | B44: =IF(B9=0,"",B9) -> DSL-DHK | C44: =IF(C9=0,"",C9) -> Md. Nazmul Hasan Titu | D44: =IF(D9=0,"",D9) -> 2913 | E44: `01816461480 | G44: =SUM(H44:S44) -> 1237500 | H44: =$J$38*H9*$L$38 -> 112500 | I44: =$J$38*H9*$L$38+$N$38*I9*$P$38 -> 112500 | J44: =$J$38*I9*$L$38+$N$38*J9*$P$38 -> 0 | K44: =$J$38*J9*$L$38+$N$38*K9*$P$38 -> 0 | L44: =$J$38*K9*$L$38+$N$38*L9*$P$38 -> 0 | M44: =$J$38*L9*$L$38+$N$38*M9*$P$38 -> 0 | N44: =$J$38*M9*$L$38+$N$38*N9*$P$38 -> 0 | O44: =$J$38*N9*$L$38+$N$38*O9*$P$38 -> 112500 | P44: =$J$38*O9*$L$38+$N$38*P9*$P$38 -> 225000 | ... S44: =$J$38*R9*$L$38+$N$38*S9*$P$38 -> 225000
A45: =A10 -> 5 | B45: =IF(B10=0,"",B10) -> DSL-DHK | C45: =IF(C10=0,"",C10) -> Md. Zahirul Islam | D45: =IF(D10=0,"",D10) -> 2914 | E45: `01870236390 | G45: =SUM(H45:S45) -> 4590000 | H45: =$J$38*H10*$L$38 -> 450000 | I45: =$J$38*H10*$L$38+$N$38*I10*$P$38 -> 450000 | J45: =$J$38*I10*$L$38+$N$38*J10*$P$38 -> 0 | K45: =$J$38*J10*$L$38+$N$38*K10*$P$38 -> 0 | L45: =$J$38*K10*$L$38+$N$38*L10*$P$38 -> 0 | M45: =$J$38*L10*$L$38+$N$38*M10*$P$38 -> 0 | N45: =$J$38*M10*$L$38+$N$38*N10*$P$38 -> 0 | O45: =$J$38*N10*$L$38+$N$38*O10*$P$38 -> 360000 | P45: =$J$38*O10*$L$38+$N$38*P10*$P$38 -> 720000 | ... S45: =$J$38*R10*$L$38+$N$38*S10*$P$38 -> 900000
...

Sheet Sheet1
E1: 2701 | F1: 250000 | G1: =VLOOKUP(E1,$K$3:$L$26,2,FALSE) -> 178 | H1: 0
E2: 2330 | F2: 2000000 | G2: =VLOOKUP(E2,$K$3:$L$26,2,FALSE) -> 179 | H2: 0
E3: 2913 | F3: 1500000 | G3: =VLOOKUP(E3,$K$3:$L$26,2,FALSE) -> 180 | H3: 250000 | K3: 1418 | L3: 177 | M3: Md. Shohidul
E4: 2914 | F4: 5600000 | G4: =VLOOKUP(E4,$K$3:$L$26,2,FALSE) -> 181 | H4: 1000000 | K4: 2701 | L4: 178 | M4: Sagar Chakrobarti
E5: 2927 | F5: 1900000 | G5: =VLOOKUP(E5,$K$3:$L$26,2,FALSE) -> 182 | H5: 300000 | K5: 2330 | L5: 179 | M5: Md. Minhazul Islam
E6: 2699 | F6: 2000000 | G6: =VLOOKUP(E6,$K$3:$L$26,2,FALSE) -> 183 | H6: 400000 | K6: 2913 | L6: 180 | M6: Md. Nazmul Hasan Titu
E7: 3002 | F7: 3600000 | G7: =VLOOKUP(E7,$K$3:$L$26,2,FALSE) -> 184 | H7: 600000 | K7: 2914 | L7: 181 | M7: Md. Zahirul Islam
E8: 3004 | F8: 3600000 | G8: =VLOOKUP(E8,$K$3:$L$26,2,FALSE) -> 185 | H8: 600000 | K8: 2927 | L8: 182 | M8: Md. Rakibul Hasan
E9: 3006 | F9: 1210000 | G9: =VLOOKUP(E9,$K$3:$L$26,2,FALSE) -> 186 | H9: 250000 | K9: 2699 | L9: 183 | M9: Md Ariful Islam
E10: 3003 | F10: 3600000 | G10: =VLOOKUP(E10,$K$3:$L$26,2,FALSE) -> 187 | H10: 500000 | K10: 3002 | L10: 184 | M10: Mohammad Jewel Rana
E11: 5690 | F11: 3600000 | G11: =VLOOKUP(E11,$K$3:$L$26,2,FALSE) -> 188 | H11: 600000 | K11: 3004 | L11: 185 | M11: Faysal Ahmed
E12: 5691 | F12: 1900000 | G12: =VLOOKUP(E12,$K$3:$L$26,2,FALSE) -> 189 | H12: 300000 | K12: 3006 | L12: 186 | M12: Rakibul Islam Razib
E13: 5692 | F13: 2700000 | G13: =VLOOKUP(E13,$K$3:$L$26,2,FALSE) -> 190 | H13: 400000 | K13: 3003 | L13: 187 | M13: Ashraful Islam
E14: 5927 | F14: 1150000 | G14: =VLOOKUP(E14,$K$3:$L$26,2,FALSE) -> 191 | H14: 230000 | K14: 5690 | L14: 188 | M14: Md. Rakibul Islam
... E19: 6078 | F19: 1200000 | G19: =VLOOKUP(E19,$K$3:$L$26,2,FALSE) -> 198 | H19: 600000 | K19: 5929 | L19: 193 | M19: Md. Jafor Ikbal
E20: 0522 | F20: 4350000 | G20: =VLOOKUP(E20,$K$3:$L$26,2,FALSE) -> 203 | H20: 900000 | K20: 8041 | L20: 194 | M20: Sumon Sen
E21: 8041 | F21: 2250000 | G21: =VLOOKUP(E21,$K$3:$L$26,2,FALSE) -> 194 | H21: 0 | K21: 1475 | L21: 195 | M21: Tapan Barua
E22: 1475 | F22: 2250000 | G22: =VLOOKUP(E22,$K$3:$L$26,2,FALSE) -> 195 | H22: 0 | K22: 6076 | L22: 196 | M22: Sozol Prince
E23: 6076 | F23: 2250000 | G23: =VLOOKUP(E23,$K$3:$L$26,2,FALSE) -> 196 | H23: 0 | K23: 6080 | L23: 197 | M23: Ashikur Rahman
K24: 6078 | L24: 198 | M24: Md. Sujon Hossain
K25: 6079 | L25: 199 | M25: Md. Habibur Rahman
K26: 0522 | L26: 203 | M26: Md Jiaur Rahman

Sheet Upload
A1: ID | B1: BU | C1: ASEUID | D1: MonthYearName | E1: TargetType | F1: StartDate | G1: EndDate | H1: TargetAmount | I1: AchievedPerc | J1: AchievedAmount | K1: NewContract | L1: RenewContract | M1: UserID | N1: EntryDateTime | O1: HostName
A2: 1001 | B2: 2 | C2: 177 | D2: FY 2022-23 | E2: 2 | F2: 44743 | G2: 45107 | H2: 2700000 | I2: 0 | J2: 25000 | K2: 0 | L2: 0 | M2: 160 | N2: 44805.706 | O2: 127.0.0.1
A3: 1002 | B3: 2 | C3: 178 | D3: FY 2022-24 | E3: 2 | F3: 44743 | G3: 45107 | H3: 250000 | I3: 0 | J3: 25000 | K3: 0 | L3: 0 | M3: 160 | N3: 44805.706 | O3: 127.0.0.1
A4: 1003 | B4: 2 | C4: 179 | D4: FY 2022-25 | E4: 2 | F4: 44743 | G4: 45107 | H4: 2000000 | I4: 0 | J4: 25000 | K4: 0 | L4: 0 | M4: 160 | N4: 44805.706 | O4: 127.0.0.1
A5: 1004 | B5: 2 | C5: 180 | D5: FY 2022-26 | E5: 2 | F5: 44743 | G5: 45107 | H5: 1500000 | I5: 0 | J5: 25000 | K5: 0 | L5: 0 | M5: 160 | N5: 44805.706 | O5: 127.0.0.1
A6: 1005 | B6: 2 | C6: 181 | D6: FY 2022-27 | E6: 2 | F6: 44743 | G6: 45107 | H6: 5600000 | I6: 0 | J6: 25000 | K6: 0 | L6: 0 | M6: 160 | N6: 44805.706 | O6: 127.0.0.1
A7: 1006 | B7: 2 | C7: 182 | D7: FY 2022-28 | E7: 2 | F7: 44743 | G7: 45107 | H7: 1900000 | I7: 0 | J7: 25000 | K7: 0 | L7: 0 | M7: 160 | N7: 44805.706 | O7: 127.0.0.1
A8: 1007 | B8: 2 | C8: 183 | D8: FY 2022-29 | E8: 2 | F8: 44743 | G8: 45107 | H8: 2000000 | I8: 0 | J8: 25000 | K8: 0 | L8: 0 | M8: 160 | N8: 44805.706 | O8: 127.0.0.1
A9: 1008 | B9: 2 | C9: 184 | D9: FY 2022-30 | E9: 2 | F9: 44743 | G9: 45107 | H9: 3600000 | I9: 0 | J9: 25000 | K9: 0 | L9: 0 | M9: 160 | N9: 44805.706 | O9: 127.0.0.1
A10: 1009 | B10: 2 | C10: 185 | D10: FY 2022-31 | E10: 2 | F10: 44743 | G10: 45107 | H10: 3600000 | I10: 0 | J10: 25000 | K10: 0 | L10: 0 | M10: 160 | N10: 44805.706 | O10: 127.0.0.1
A11: 1010 | B11: 2 | C11: 186 | D11: FY 2022-32 | E11: 2 | F11: 44743 | G11: 45107 | H11: 1210000 | I11: 0 | J11: 25000 | K11: 0 | L11: 0 | M11: 160 | N11: 44805.706 | O11: 127.0.0.1
A12: 1011 | B12: 2 | C12: 187 | D12: FY 2022-33 | E12: 2 | F12: 44743 | G12: 45107 | H12: 3600000 | I12: 0 | J12: 25000 | K12: 0 | L12: 0 | M12: 160 | N12: 44805.706 | O12: 127.0.0.1
A13: 1012 | B13: 2 | C13: 188 | D13: FY 2022-34 | E13: 2 | F13: 44743 | G13: 45107 | H13: 3600000 | I13: 0 | J13: 25000 | K13: 0 | L13: 0 | M13: 160 | N13: 44805.706 | O13: 127.0.0.1
... A49: 1048 | B49: 2 | C49: 196 | D49: July, 2022 | E49: 1 | F49: 44743 | G49: 44773 | H49: 0 | I49: 1 | J49: 0 | K49: 0 | L49: 0 | M49: 160 | N49: 44807.047 | O49: 127.0.0.1

Sheet ASE Target vs Ach(Spares)(Inpt)
C2: ='ASE Ach(Lube Oil Sales)'!B2 -> Month | D2: ='ASE Ach(Lube Oil Sales)'!C2 -> Jul | E2: ='ASE Ach(Lube Oil Sales)'!D2 -> <<< No input
B4: Sales (Spares) | G4: input▼ | J4: input▼ | M4: input▼ | P4: input▼ | S4: input▼ | V4: input▼ | Y4: input▼ | AB4: input▼ | AE4: input▼ | AH4: input▼ | AK4: input▼ | AN4: input▼
B5: ='ASE Target (Spares), FY 21-22'!A5 -> Sl. | C5: ='ASE Target (Spares), FY 21-22'!B5 -> Wing | D5: ='ASE Target (Spares), FY 21-22'!C5 -> Name | E5: ='ASE Target (Spares), FY 21-22'!D5 -> ID | F5: Jul | I5: Aug | L5: Sep | O5: Oct | R5: Nov | U5: Dec | X5: Jan | AA5: Feb | AD5: Mar | AG5: Apr | AJ5: May | AM5: Jun | AP5: Total (Jul-May)
F6: Target | G6: Ach | H6: Ach (%) | I6: Target | J6: Ach | K6: Ach (%) | L6: Target | M6: Ach | N6: Ach (%) | O6: Target | P6: Ach | Q6: Ach (%) | R6: Target | S6: Ach | T6: Ach (%) | U6: Target | V6: Ach | W6: Ach (%) | X6: Target | Y6: Ach | Z6: Ach (%) | AA6: Target | AB6: Ach | AC6: Ach (%) | AD6: Target | AE6: Ach | AF6: Ach (%) | AG6: Target | AH6: Ach | AI6: Ach (%) | AJ6: Target | AK6: Ach | AL6: Ach (%) | AM6: Target | AN6: Ach | AO6: Ach (%) | AP6: Target | AQ6: Ach | AR6: Ach (%)
B7: ='ASE Target (Spares), FY 21-22'!A6 -> 1 | C7: =IF('ASE Target (Spares), FY 21-22'!B6=0,"",'ASE Target (Spares), FY 21-22'!B6) -> DSL-DHK | D7: =IF('ASE Target (Spares), FY 21-22'!C6=0,"",'ASE Target (Spares), FY 21-22'!C6) -> Md. Shohidul | E7: =IF('ASE Target (Spares), FY 21-22'!D6=0,"",'ASE Target (Spares), FY 21-22'!D6) -> 1418 | F7: =IFERROR(VLOOKUP(D7,'ASE Target (Spares), FY 21-22'!$C$5:$H$39,6,0),"") -> 500000 | G7: 1547635 | H7: =IFERROR(G7/F7,"") -> 3.09527 | I7: =IFERROR(VLOOKUP(D7,'ASE Target (Spares), FY 21-22'!$C$5:$I$39,7,0),"") -> 0 | K7: =IFERROR(J7/I7,"") | L7: =IFERROR(VLOOKUP(D7,'ASE Target (Spares), FY 21-22'!$C$5:$J$39,8,0),"") -> 0 | N7: =IFERROR(M7/L7,"") | O7: =IFERROR(VLOOKUP(D7,'ASE Target (Spares), FY 21-22'!$C$5:$K$39,9,0),"") -> 0 | Q7: =IFERROR(P7/O7,"") | R7: =IFERROR(VLOOKUP(D7,'ASE Target (Spares), FY 21-22'!$C$5:$L$39,10,0),"") -> 0 | T7: =IFERROR(S7/R7,"") | U7: =IFERROR(VLOOKUP(D7,'ASE Target (Spares), FY 21-22'!$C$5:$M$39,11,0),"") -> 0 | W7: =IFERROR(V7/U7,"") | X7: =IFERROR(VLOOKUP(D7,'ASE Target (Spares), FY 21-22'!$C$5:$N$39,12,0),"") -> 0 | Z7: =IFERROR(Y7/X7,"") | AA7: =IFERROR(VLOOKUP(D7,'ASE Target (Spares), FY 21-22'!$C$5:$O$39,13,0),"") -> 600000 | AC7: =IFERROR(AB7/AA7,"") -> 0 | AD7: =IFERROR(VLOOKUP(D7,'ASE Target (Spares), FY 21-22'!$C$5:$P$39,14,0),"") -> 300000 | AF7: =IFERROR(AE7/AD7,"") -> 0 | AG7: =IFERROR(VLOOKUP(D7,'ASE Target (Spares), FY 21-22'!$C$5:$Q$39,15,0),"") -> 400000 | AI7: =IFERROR(AH7/AG7,"") -> 0 | AJ7: =IFERROR(VLOOKUP(D7,'ASE Target (Spares), FY 21-22'!$C$5:$R$39,16,0),"") -> 400000 | AL7: =IFERROR(AK7/AJ7,"") -> 0 | AM7: =IFERROR(VLOOKUP(D7,'ASE Target (Spares), FY 21-22'!$C$5:$S$39,17,0),"") -> 500000 | AO7: =IFERROR(AN7/AM7,"") -> 0 | AP7: =IFERROR(F7+I7+L7+O7+R7+U7+X7+AA7+AD7+AG7+AJ7+AM7,"") -> 2700000 | AQ7: =IFERROR(G7+J7+M7+P7+S7+V7+Y7+AB7+AE7+AH7+AK7+AN7,"") -> 1547635 | AR7: =IFERROR(AQ7/AP7,"") -> 0.57319815
B8: ='ASE Target (Spares), FY 21-22'!A7 -> 2 | C8: =IF('ASE Target (Spares), FY 21-22'!B7=0,"",'ASE Target (Spares), FY 21-22'!B7) -> DSL-DHK | D8: =IF('ASE Target (Spares), FY 21-22'!C7=0,"",'ASE Target (Spares), FY 21-22'!C7) -> Sagar Chakrobarti | E8: =IF('ASE Target (Spares), FY 21-22'!D7=0,"",'ASE Target (Spares), FY 21-22'!D7) -> 2701 | F8: =IFERROR(VLOOKUP(D8,'ASE Target (Spares), FY 21-22'!$C$5:$H$39,6,0),"") -> 0 | H8: =IFERROR(G8/F8,"") | I8: =IFERROR(VLOOKUP(D8,'ASE Target (Spares), FY 21-22'!$C$5:$I$39,7,0),"") -> 0 | K8: =IFERROR(J8/I8,"") | L8: =IFERROR(VLOOKUP(D8,'ASE Target (Spares), FY 21-22'!$C$5:$J$39,8,0),"") -> 0 | N8: =IFERROR(M8/L8,"") | O8: =IFERROR(VLOOKUP(D8,'ASE Target (Spares), FY 21-22'!$C$5:$K$39,9,0),"") -> 0 | Q8: =IFERROR(P8/O8,"") | R8: =IFERROR(VLOOKUP(D8,'ASE Target (Spares), FY 21-22'!$C$5:$L$39,10,0),"") -> 0 | T8: =IFERROR(S8/R8,"") | U8: =IFERROR(VLOOKUP(D8,'ASE Target (Spares), FY 21-22'!$C$5:$M$39,11,0),"") -> 0 | W8: =IFERROR(V8/U8,"") | X8: =IFERROR(VLOOKUP(D8,'ASE Target (Spares), FY 21-22'!$C$5:$N$39,12,0),"") -> 0 | Z8: =IFERROR(Y8/X8,"") | AA8: =IFERROR(VLOOKUP(D8,'ASE Target (Spares), FY 21-22'!$C$5:$O$39,13,0),"") -> 250000 | AC8: =IFERROR(AB8/AA8,"") -> 0 | AD8: =IFERROR(VLOOKUP(D8,'ASE Target (Spares), FY 21-22'!$C$5:$P$39,14,0),"") -> 0 | AF8: =IFERROR(AE8/AD8,"") | AG8: =IFERROR(VLOOKUP(D8,'ASE Target (Spares), FY 21-22'!$C$5:$Q$39,15,0),"") -> 0 | AI8: =IFERROR(AH8/AG8,"") | AJ8: =IFERROR(VLOOKUP(D8,'ASE Target (Spares), FY 21-22'!$C$5:$R$39,16,0),"") -> 0 | AL8: =IFERROR(AK8/AJ8,"") | AM8: =IFERROR(VLOOKUP(D8,'ASE Target (Spares), FY 21-22'!$C$5:$S$39,17,0),"") -> 0 | AO8: =IFERROR(AN8/AM8,"") | AP8: =IFERROR(F8+I8+L8+O8+R8+U8+X8+AA8+AD8+AG8+AJ8+AM8,"") -> 250000 | AQ8: =IFERROR(G8+J8+M8+P8+S8+V8+Y8+AB8+AE8+AH8+AK8+AN8,"") -> 0 | AR8: =IFERROR(AQ8/AP8,"") -> 0
B9: ='ASE Target (Spares), FY 21-22'!A8 -> 3 | C9: =IF('ASE Target (Spares), FY 21-22'!B8=0,"",'ASE Target (Spares), FY 21-22'!B8) -> DSL-DHK | D9: =IF('ASE Target (Spares), FY 21-22'!C8=0,"",'ASE Target (Spares), FY 21-22'!C8) -> Md. Minhazul Islam | E9: =IF('ASE Target (Spares), FY 21-22'!D8=0,"",'ASE Target (Spares), FY 21-22'!D8) -> 2330 | F9: =IFERROR(VLOOKUP(D9,'ASE Target (Spares), FY 21-22'!$C$5:$H$39,6,0),"") -> 0 | H9: =IFERROR(G9/F9,"") | I9: =IFERROR(VLOOKUP(D9,'ASE Target (Spares), FY 21-22'!$C$5:$I$39,7,0),"") -> 0 | K9: =IFERROR(J9/I9,"") | L9: =IFERROR(VLOOKUP(D9,'ASE Target (Spares), FY 21-22'!$C$5:$J$39,8,0),"") -> 0 | N9: =IFERROR(M9/L9,"") | O9: =IFERROR(VLOOKUP(D9,'ASE Target (Spares), FY 21-22'!$C$5:$K$39,9,0),"") -> 0 | Q9: =IFERROR(P9/O9,"") | R9: =IFERROR(VLOOKUP(D9,'ASE Target (Spares), FY 21-22'!$C$5:$L$39,10,0),"") -> 0 | T9: =IFERROR(S9/R9,"") | U9: =IFERROR(VLOOKUP(D9,'ASE Target (Spares), FY 21-22'!$C$5:$M$39,11,0),"") -> 0 | W9: =IFERROR(V9/U9,"") | X9: =IFERROR(VLOOKUP(D9,'ASE Target (Spares), FY 21-22'!$C$5:$N$39,12,0),"") -> 0 | Z9: =IFERROR(Y9/X9,"") | AA9: =IFERROR(VLOOKUP(D9,'ASE Target (Spares), FY 21-22'!$C$5:$O$39,13,0),"") -> 1000000 | AC9: =IFERROR(AB9/AA9,"") -> 0 | AD9: =IFERROR(VLOOKUP(D9,'ASE Target (Spares), FY 21-22'!$C$5:$P$39,14,0),"") -> 1000000 | AF9: =IFERROR(AE9/AD9,"") -> 0 | AG9: =IFERROR(VLOOKUP(D9,'ASE Target (Spares), FY 21-22'!$C$5:$Q$39,15,0),"") -> 0 | AI9: =IFERROR(AH9/AG9,"") | AJ9: =IFERROR(VLOOKUP(D9,'ASE Target (Spares), FY 21-22'!$C$5:$R$39,16,0),"") -> 0 | AL9: =IFERROR(AK9/AJ9,"") | AM9: =IFERROR(VLOOKUP(D9,'ASE Target (Spares), FY 21-22'!$C$5:$S$39,17,0),"") -> 0 | AO9: =IFERROR(AN9/AM9,"") | AP9: =IFERROR(F9+I9+L9+O9+R9+U9+X9+AA9+AD9+AG9+AJ9+AM9,"") -> 2000000 | AQ9: =IFERROR(G9+J9+M9+P9+S9+V9+Y9+AB9+AE9+AH9+AK9+AN9,"") -> 0 | AR9: =IFERROR(AQ9/AP9,"") -> 0
B10: ='ASE Target (Spares), FY 21-22'!A9 -> 4 | C10: =IF('ASE Target (Spares), FY 21-22'!B9=0,"",'ASE Target (Spares), FY 21-22'!B9) -> DSL-DHK | D10: =IF('ASE Target (Spares), FY 21-22'!C9=0,"",'ASE Target (Spares), FY 21-22'!C9) -> Md. Nazmul Hasan Titu | E10: =IF('ASE Target (Spares), FY 21-22'!D9=0,"",'ASE Target (Spares), FY 21-22'!D9) -> 2913 | F10: =IFERROR(VLOOKUP(D10,'ASE Target (Spares), FY 21-22'!$C$5:$H$39,6,0),"") -> 250000 | G10: 709063 | H10: =IFERROR(G10/F10,"") -> 2.836252 | I10: =IFERROR(VLOOKUP(D10,'ASE Target (Spares), FY 21-22'!$C$5:$I$39,7,0),"") -> 0 | K10: =IFERROR(J10/I10,"") | L10: =IFERROR(VLOOKUP(D10,'ASE Target (Spares), FY 21-22'!$C$5:$J$39,8,0),"") -> 0 | N10: =IFERROR(M10/L10,"") | O10: =IFERROR(VLOOKUP(D10,'ASE Target (Spares), FY 21-22'!$C$5:$K$39,9,0),"") -> 0 | Q10: =IFERROR(P10/O10,"") | R10: =IFERROR(VLOOKUP(D10,'ASE Target (Spares), FY 21-22'!$C$5:$L$39,10,0),"") -> 0 | T10: =IFERROR(S10/R10,"") | U10: =IFERROR(VLOOKUP(D10,'ASE Target (Spares), FY 21-22'!$C$5:$M$39,11,0),"") -> 0 | W10: =IFERROR(V10/U10,"") | X10: =IFERROR(VLOOKUP(D10,'ASE Target (Spares), FY 21-22'!$C$5:$N$39,12,0),"") -> 0 | Z10: =IFERROR(Y10/X10,"") | AA10: =IFERROR(VLOOKUP(D10,'ASE Target (Spares), FY 21-22'!$C$5:$O$39,13,0),"") -> 250000 | AC10: =IFERROR(AB10/AA10,"") -> 0 | AD10: =IFERROR(VLOOKUP(D10,'ASE Target (Spares), FY 21-22'!$C$5:$P$39,14,0),"") -> 250000 | AF10: =IFERROR(AE10/AD10,"") -> 0 | AG10: =IFERROR(VLOOKUP(D10,'ASE Target (Spares), FY 21-22'!$C$5:$Q$39,15,0),"") -> 250000 | AI10: =IFERROR(AH10/AG10,"") -> 0 | AJ10: =IFERROR(VLOOKUP(D10,'ASE Target (Spares), FY 21-22'!$C$5:$R$39,16,0),"") -> 250000 | AL10: =IFERROR(AK10/AJ10,"") -> 0 | AM10: =IFERROR(VLOOKUP(D10,'ASE Target (Spares), FY 21-22'!$C$5:$S$39,17,0),"") -> 250000 | AO10: =IFERROR(AN10/AM10,"") -> 0 | AP10: =IFERROR(F10+I10+L10+O10+R10+U10+X10+AA10+AD10+AG10+AJ10+AM10,"") -> 1500000 | AQ10: =IFERROR(G10+J10+M10+P10+S10+V10+Y10+AB10+AE10+AH10+AK10+AN10,"") -> 709063 | AR10: =IFERROR(AQ10/AP10,"") -> 0.47270867
B11: ='ASE Target (Spares), FY 21-22'!A10 -> 5 | C11: =IF('ASE Target (Spares), FY 21-22'!B10=0,"",'ASE Target (Spares), FY 21-22'!B10) -> DSL-DHK | D11: =IF('ASE Target (Spares), FY 21-22'!C10=0,"",'ASE Target (Spares), FY 21-22'!C10) -> Md. Zahirul Islam | E11: =IF('ASE Target (Spares), FY 21-22'!D10=0,"",'ASE Target (Spares), FY 21-22'!D10) -> 2914 | F11: =IFERROR(VLOOKUP(D11,'ASE Target (Spares), FY 21-22'!$C$5:$H$39,6,0),"") -> 1000000 | G11: 764379 | H11: =IFERROR(G11/F11,"") -> 0.764379 | I11: =IFERROR(VLOOKUP(D11,'ASE Target (Spares), FY 21-22'!$C$5:$I$39,7,0),"") -> 0 | K11: =IFERROR(J11/I11,"") | L11: =IFERROR(VLOOKUP(D11,'ASE Target (Spares), FY 21-22'!$C$5:$J$39,8,0),"") -> 0 | N11: =IFERROR(M11/L11,"") | O11: =IFERROR(VLOOKUP(D11,'ASE Target (Spares), FY 21-22'!$C$5:$K$39,9,0),"") -> 0 | Q11: =IFERROR(P11/O11,"") | R11: =IFERROR(VLOOKUP(D11,'ASE Target (Spares), FY 21-22'!$C$5:$L$39,10,0),"") -> 0 | T11: =IFERROR(S11/R11,"") | U11: =IFERROR(VLOOKUP(D11,'ASE Target (Spares), FY 21-22'!$C$5:$M$39,11,0),"") -> 0 | W11: =IFERROR(V11/U11,"") | X11: =IFERROR(VLOOKUP(D11,'ASE Target (Spares), FY 21-22'!$C$5:$N$39,12,0),"") -> 0 | Z11: =IFERROR(Y11/X11,"") | AA11: =IFERROR(VLOOKUP(D11,'ASE Target (Spares), FY 21-22'!$C$5:$O$39,13,0),"") -> 800000 | AC11: =IFERROR(AB11/AA11,"") -> 0 | AD11: =IFERROR(VLOOKUP(D11,'ASE Target (Spares), FY 21-22'!$C$5:$P$39,14,0),"") -> 800000 | AF11: =IFERROR(AE11/AD11,"") -> 0 | AG11: =IFERROR(VLOOKUP(D11,'ASE Target (Spares), FY 21-22'!$C$5:$Q$39,15,0),"") -> 1000000 | AI11: =IFERROR(AH11/AG11,"") -> 0 | AJ11: =IFERROR(VLOOKUP(D11,'ASE Target (Spares), FY 21-22'!$C$5:$R$39,16,0),"") -> 1000000 | AL11: =IFERROR(AK11/AJ11,"") -> 0 | AM11: =IFERROR(VLOOKUP(D11,'ASE Target (Spares), FY 21-22'!$C$5:$S$39,17,0),"") -> 1000000 | AO11: =IFERROR(AN11/AM11,"") -> 0 | AP11: =IFERROR(F11+I11+L11+O11+R11+U11+X11+AA11+AD11+AG11+AJ11+AM11,"") -> 5600000 | AQ11: =IFERROR(G11+J11+M11+P11+S11+V11+Y11+AB11+AE11+AH11+AK11+AN11,"") -> 764379 | AR11: =IFERROR(AQ11/AP11,"") -> 0.13649625
B12: ='ASE Target (Spares), FY 21-22'!A11 -> 6 | C12: =IF('ASE Target (Spares), FY 21-22'!B11=0,"",'ASE Target (Spares), FY 21-22'!B11) -> DSL-DHK | D12: =IF('ASE Target (Spares), FY 21-22'!C11=0,"",'ASE Target (Spares), FY 21-22'!C11) -> Md. Rakibul Hasan | E12: =IF('ASE Target (Spares), FY 21-22'!D11=0,"",'ASE Target (Spares), FY 21-22'!D11) -> 2927 | F12: =IFERROR(VLOOKUP(D12,'ASE Target (Spares), FY 21-22'!$C$5:$H$39,6,0),"") -> 300000 | G12: 1061650 | H12: =IFERROR(G12/F12,"") -> 3.5388333 | I12: =IFERROR(VLOOKUP(D12,'ASE Target (Spares), FY 21-22'!$C$5:$I$39,7,0),"") -> 0 | K12: =IFERROR(J12/I12,"") | L12: =IFERROR(VLOOKUP(D12,'ASE Target (Spares), FY 21-22'!$C$5:$J$39,8,0),"") -> 0 | N12: =IFERROR(M12/L12,"") | O12: =IFERROR(VLOOKUP(D12,'ASE Target (Spares), FY 21-22'!$C$5:$K$39,9,0),"") -> 0 | Q12: =IFERROR(P12/O12,"") | R12: =IFERROR(VLOOKUP(D12,'ASE Target (Spares), FY 21-22'!$C$5:$L$39,10,0),"") -> 0 | T12: =IFERROR(S12/R12,"") | U12: =IFERROR(VLOOKUP(D12,'ASE Target (Spares), FY 21-22'!$C$5:$M$39,11,0),"") -> 0 | W12: =IFERROR(V12/U12,"") | X12: =IFERROR(VLOOKUP(D12,'ASE Target (Spares), FY 21-22'!$C$5:$N$39,12,0),"") -> 0 | Z12: =IFERROR(Y12/X12,"") | AA12: =IFERROR(VLOOKUP(D12,'ASE Target (Spares), FY 21-22'!$C$5:$O$39,13,0),"") -> 400000 | AC12: =IFERROR(AB12/AA12,"") -> 0 | AD12: =IFERROR(VLOOKUP(D12,'ASE Target (Spares), FY 21-22'!$C$5:$P$39,14,0),"") -> 300000 | AF12: =IFERROR(AE12/AD12,"") -> 0 | AG12: =IFERROR(VLOOKUP(D12,'ASE Target (Spares), FY 21-22'!$C$5:$Q$39,15,0),"") -> 300000 | AI12: =IFERROR(AH12/AG12,"") -> 0 | AJ12: =IFERROR(VLOOKUP(D12,'ASE Target (Spares), FY 21-22'!$C$5:$R$39,16,0),"") -> 300000 | AL12: =IFERROR(AK12/AJ12,"") -> 0 | AM12: =IFERROR(VLOOKUP(D12,'ASE Target (Spares), FY 21-22'!$C$5:$S$39,17,0),"") -> 300000 | AO12: =IFERROR(AN12/AM12,"") -> 0 | AP12: =IFERROR(F12+I12+L12+O12+R12+U12+X12+AA12+AD12+AG12+AJ12+AM12,"") -> 1900000 | AQ12: =IFERROR(G12+J12+M12+P12+S12+V12+Y12+AB12+AE12+AH12+AK12+AN12,"") -> 1061650 | AR12: =IFERROR(AQ12/AP12,"") -> 0.55876316
B13: ='ASE Target (Spares), FY 21-22'!A12 -> 7 | C13: =IF('ASE Target (Spares), FY 21-22'!B12=0,"",'ASE Target (Spares), FY 21-22'!B12) -> DSL-DHK | D13: =IF('ASE Target (Spares), FY 21-22'!C12=0,"",'ASE Target (Spares), FY 21-22'!C12) -> Md Ariful Islam | E13: =IF('ASE Target (Spares), FY 21-22'!D12=0,"",'ASE Target (Spares), FY 21-22'!D12) -> 2699 | F13: =IFERROR(VLOOKUP(D13,'ASE Target (Spares), FY 21-22'!$C$5:$H$39,6,0),"") -> 400000 | H13: =IFERROR(G13/F13,"") -> 0 | I13: =IFERROR(VLOOKUP(D13,'ASE Target (Spares), FY 21-22'!$C$5:$I$39,7,0),"") -> 0 | K13: =IFERROR(J13/I13,"") | L13: =IFERROR(VLOOKUP(D13,'ASE Target (Spares), FY 21-22'!$C$5:$J$39,8,0),"") -> 0 | N13: =IFERROR(M13/L13,"") | O13: =IFERROR(VLOOKUP(D13,'ASE Target (Spares), FY 21-22'!$C$5:$K$39,9,0),"") -> 0 | Q13: =IFERROR(P13/O13,"") | R13: =IFERROR(VLOOKUP(D13,'ASE Target (Spares), FY 21-22'!$C$5:$L$39,10,0),"") -> 0 | T13: =IFERROR(S13/R13,"") | U13: =IFERROR(VLOOKUP(D13,'ASE Target (Spares), FY 21-22'!$C$5:$M$39,11,0),"") -> 0 | W13: =IFERROR(V13/U13,"") | X13: =IFERROR(VLOOKUP(D13,'ASE Target (Spares), FY 21-22'!$C$5:$N$39,12,0),"") -> 0 | Z13: =IFERROR(Y13/X13,"") | AA13: =IFERROR(VLOOKUP(D13,'ASE Target (Spares), FY 21-22'!$C$5:$O$39,13,0),"") -> 0 | AC13: =IFERROR(AB13/AA13,"") | AD13: =IFERROR(VLOOKUP(D13,'ASE Target (Spares), FY 21-22'!$C$5:$P$39,14,0),"") -> 400000 | AF13: =IFERROR(AE13/AD13,"") -> 0 | AG13: =IFERROR(VLOOKUP(D13,'ASE Target (Spares), FY 21-22'!$C$5:$Q$39,15,0),"") -> 400000 | AI13: =IFERROR(AH13/AG13,"") -> 0 | AJ13: =IFERROR(VLOOKUP(D13,'ASE Target (Spares), FY 21-22'!$C$5:$R$39,16,0),"") -> 400000 | AL13: =IFERROR(AK13/AJ13,"") -> 0 | AM13: =IFERROR(VLOOKUP(D13,'ASE Target (Spares), FY 21-22'!$C$5:$S$39,17,0),"") -> 400000 | AO13: =IFERROR(AN13/AM13,"") -> 0 | AP13: =IFERROR(F13+I13+L13+O13+R13+U13+X13+AA13+AD13+AG13+AJ13+AM13,"") -> 2000000 | AQ13: =IFERROR(G13+J13+M13+P13+S13+V13+Y13+AB13+AE13+AH13+AK13+AN13,"") -> 0 | AR13: =IFERROR(AQ13/AP13,"") -> 0
B14: ='ASE Target (Spares), FY 21-22'!A13 -> 8 | C14: =IF('ASE Target (Spares), FY 21-22'!B13=0,"",'ASE Target (Spares), FY 21-22'!B13) -> DSL-DHK | D14: =IF('ASE Target (Spares), FY 21-22'!C13=0,"",'ASE Target (Spares), FY 21-22'!C13) -> Mohammad Jewel Rana | E14: =IF('ASE Target (Spares), FY 21-22'!D13=0,"",'ASE Target (Spares), FY 21-22'!D13) -> 3002 | F14: =IFERROR(VLOOKUP(D14,'ASE Target (Spares), FY 21-22'!$C$5:$H$39,6,0),"") -> 600000 | G14: 437175 | H14: =IFERROR(G14/F14,"") -> 0.728625 | I14: =IFERROR(VLOOKUP(D14,'ASE Target (Spares), FY 21-22'!$C$5:$I$39,7,0),"") -> 0 | K14: =IFERROR(J14/I14,"") | L14: =IFERROR(VLOOKUP(D14,'ASE Target (Spares), FY 21-22'!$C$5:$J$39,8,0),"") -> 0 | N14: =IFERROR(M14/L14,"") | O14: =IFERROR(VLOOKUP(D14,'ASE Target (Spares), FY 21-22'!$C$5:$K$39,9,0),"") -> 0 | Q14: =IFERROR(P14/O14,"") | R14: =IFERROR(VLOOKUP(D14,'ASE Target (Spares), FY 21-22'!$C$5:$L$39,10,0),"") -> 0 | T14: =IFERROR(S14/R14,"") | U14: =IFERROR(VLOOKUP(D14,'ASE Target (Spares), FY 21-22'!$C$5:$M$39,11,0),"") -> 0 | W14: =IFERROR(V14/U14,"") | X14: =IFERROR(VLOOKUP(D14,'ASE Target (Spares), FY 21-22'!$C$5:$N$39,12,0),"") -> 0 | Z14: =IFERROR(Y14/X14,"") | AA14: =IFERROR(VLOOKUP(D14,'ASE Target (Spares), FY 21-22'!$C$5:$O$39,13,0),"") -> 600000 | AC14: =IFERROR(AB14/AA14,"") -> 0 | AD14: =IFERROR(VLOOKUP(D14,'ASE Target (Spares), FY 21-22'!$C$5:$P$39,14,0),"") -> 600000 | AF14: =IFERROR(AE14/AD14,"") -> 0 | AG14: =IFERROR(VLOOKUP(D14,'ASE Target (Spares), FY 21-22'!$C$5:$Q$39,15,0),"") -> 600000 | AI14: =IFERROR(AH14/AG14,"") -> 0 | AJ14: =IFERROR(VLOOKUP(D14,'ASE Target (Spares), FY 21-22'!$C$5:$R$39,16,0),"") -> 600000 | AL14: =IFERROR(AK14/AJ14,"") -> 0 | AM14: =IFERROR(VLOOKUP(D14,'ASE Target (Spares), FY 21-22'!$C$5:$S$39,17,0),"") -> 600000 | AO14: =IFERROR(AN14/AM14,"") -> 0 | AP14: =IFERROR(F14+I14+L14+O14+R14+U14+X14+AA14+AD14+AG14+AJ14+AM14,"") -> 3600000 | AQ14: =IFERROR(G14+J14+M14+P14+S14+V14+Y14+AB14+AE14+AH14+AK14+AN14,"") -> 437175 | AR14: =IFERROR(AQ14/AP14,"") -> 0.1214375
B15: ='ASE Target (Spares), FY 21-22'!A14 -> 9 | C15: =IF('ASE Target (Spares), FY 21-22'!B14=0,"",'ASE Target (Spares), FY 21-22'!B14) -> DSL-DHK | D15: =IF('ASE Target (Spares), FY 21-22'!C14=0,"",'ASE Target (Spares), FY 21-22'!C14) -> Faysal Ahmed | E15: =IF('ASE Target (Spares), FY 21-22'!D14=0,"",'ASE Target (Spares), FY 21-22'!D14) -> 3004 | F15: =IFERROR(VLOOKUP(D15,'ASE Target (Spares), FY 21-22'!$C$5:$H$39,6,0),"") -> 600000 | G15: 505895 | H15: =IFERROR(G15/F15,"") -> 0.84315833 | I15: =IFERROR(VLOOKUP(D15,'ASE Target (Spares), FY 21-22'!$C$5:$I$39,7,0),"") -> 0 | K15: =IFERROR(J15/I15,"") | L15: =IFERROR(VLOOKUP(D15,'ASE Target (Spares), FY 21-22'!$C$5:$J$39,8,0),"") -> 0 | N15: =IFERROR(M15/L15,"") | O15: =IFERROR(VLOOKUP(D15,'ASE Target (Spares), FY 21-22'!$C$5:$K$39,9,0),"") -> 0 | Q15: =IFERROR(P15/O15,"") | R15: =IFERROR(VLOOKUP(D15,'ASE Target (Spares), FY 21-22'!$C$5:$L$39,10,0),"") -> 0 | T15: =IFERROR(S15/R15,"") | U15: =IFERROR(VLOOKUP(D15,'ASE Target (Spares), FY 21-22'!$C$5:$M$39,11,0),"") -> 0 | W15: =IFERROR(V15/U15,"") | X15: =IFERROR(VLOOKUP(D15,'ASE Target (Spares), FY 21-22'!$C$5:$N$39,12,0),"") -> 0 | Z15: =IFERROR(Y15/X15,"") | AA15: =IFERROR(VLOOKUP(D15,'ASE Target (Spares), FY 21-22'!$C$5:$O$39,13,0),"") -> 600000 | AC15: =IFERROR(AB15/AA15,"") -> 0 | AD15: =IFERROR(VLOOKUP(D15,'ASE Target (Spares), FY 21-22'!$C$5:$P$39,14,0),"") -> 600000 | AF15: =IFERROR(AE15/AD15,"") -> 0 | AG15: =IFERROR(VLOOKUP(D15,'ASE Target (Spares), FY 21-22'!$C$5:$Q$39,15,0),"") -> 600000 | AI15: =IFERROR(AH15/AG15,"") -> 0 | AJ15: =IFERROR(VLOOKUP(D15,'ASE Target (Spares), FY 21-22'!$C$5:$R$39,16,0),"") -> 600000 | AL15: =IFERROR(AK15/AJ15,"") -> 0 | AM15: =IFERROR(VLOOKUP(D15,'ASE Target (Spares), FY 21-22'!$C$5:$S$39,17,0),"") -> 600000 | AO15: =IFERROR(AN15/AM15,"") -> 0 | AP15: =IFERROR(F15+I15+L15+O15+R15+U15+X15+AA15+AD15+AG15+AJ15+AM15,"") -> 3600000 | AQ15: =IFERROR(G15+J15+M15+P15+S15+V15+Y15+AB15+AE15+AH15+AK15+AN15,"") -> 505895 | AR15: =IFERROR(AQ15/AP15,"") -> 0.14052639
B16: ='ASE Target (Spares), FY 21-22'!A15 -> 10 | C16: =IF('ASE Target (Spares), FY 21-22'!B15=0,"",'ASE Target (Spares), FY 21-22'!B15) -> DSL-DHK | D16: =IF('ASE Target (Spares), FY 21-22'!C15=0,"",'ASE Target (Spares), FY 21-22'!C15) -> Rakibul Islam Razib | E16: =IF('ASE Target (Spares), FY 21-22'!D15=0,"",'ASE Target (Spares), FY 21-22'!D15) -> 3006 | F16: =IFERROR(VLOOKUP(D16,'ASE Target (Spares), FY 21-22'!$C$5:$H$39,6,0),"") -> 250000 | G16: 129195 | H16: =IFERROR(G16/F16,"") -> 0.51678 | I16: =IFERROR(VLOOKUP(D16,'ASE Target (Spares), FY 21-22'!$C$5:$I$39,7,0),"") -> 0 | K16: =IFERROR(J16/I16,"") | L16: =IFERROR(VLOOKUP(D16,'ASE Target (Spares), FY 21-22'!$C$5:$J$39,8,0),"") -> 0 | N16: =IFERROR(M16/L16,"") | O16: =IFERROR(VLOOKUP(D16,'ASE Target (Spares), FY 21-22'!$C$5:$K$39,9,0),"") -> 0 | Q16: =IFERROR(P16/O16,"") | R16: =IFERROR(VLOOKUP(D16,'ASE Target (Spares), FY 21-22'!$C$5:$L$39,10,0),"") -> 0 | T16: =IFERROR(S16/R16,"") | U16: =IFERROR(VLOOKUP(D16,'ASE Target (Spares), FY 21-22'!$C$5:$M$39,11,0),"") -> 0 | W16: =IFERROR(V16/U16,"") | X16: =IFERROR(VLOOKUP(D16,'ASE Target (Spares), FY 21-22'!$C$5:$N$39,12,0),"") -> 0 | Z16: =IFERROR(Y16/X16,"") | AA16: =IFERROR(VLOOKUP(D16,'ASE Target (Spares), FY 21-22'!$C$5:$O$39,13,0),"") -> 0 | AC16: =IFERROR(AB16/AA16,"") | AD16: =IFERROR(VLOOKUP(D16,'ASE Target (Spares), FY 21-22'!$C$5:$P$39,14,0),"") -> 230000 | AF16: =IFERROR(AE16/AD16,"") -> 0 | AG16: =IFERROR(VLOOKUP(D16,'ASE Target (Spares), FY 21-22'!$C$5:$Q$39,15,0),"") -> 230000 | AI16: =IFERROR(AH16/AG16,"") -> 0 | AJ16: =IFERROR(VLOOKUP(D16,'ASE Target (Spares), FY 21-22'!$C$5:$R$39,16,0),"") -> 250000 | AL16: =IFERROR(AK16/AJ16,"") -> 0 | AM16: =IFERROR(VLOOKUP(D16,'ASE Target (Spares), FY 21-22'!$C$5:$S$39,17,0),"") -> 250000 | AO16: =IFERROR(AN16/AM16,"") -> 0 | AP16: =IFERROR(F16+I16+L16+O16+R16+U16+X16+AA16+AD16+AG16+AJ16+AM16,"") -> 1210000 | AQ16: =IFERROR(G16+J16+M16+P16+S16+V16+Y16+AB16+AE16+AH16+AK16+AN16,"") -> 129195 | AR16: =IFERROR(AQ16/AP16,"") -> 0.10677273
B17: ='ASE Target (Spares), FY 21-22'!A16 -> 11 | C17: =IF('ASE Target (Spares), FY 21-22'!B16=0,"",'ASE Target (Spares), FY 21-22'!B16) -> DSL-DHK | D17: =IF('ASE Target (Spares), FY 21-22'!C16=0,"",'ASE Target (Spares), FY 21-22'!C16) -> Ashraful Islam | E17: =IF('ASE Target (Spares), FY 21-22'!D16=0,"",'ASE Target (Spares), FY 21-22'!D16) -> 3003 | F17: =IFERROR(VLOOKUP(D17,'ASE Target (Spares), FY 21-22'!$C$5:$H$39,6,0),"") -> 500000 | G17: 747948 | H17: =IFERROR(G17/F17,"") -> 1.495896 | I17: =IFERROR(VLOOKUP(D17,'ASE Target (Spares), FY 21-22'!$C$5:$I$39,7,0),"") -> 0 | K17: =IFERROR(J17/I17,"") | L17: =IFERROR(VLOOKUP(D17,'ASE Target (Spares), FY 21-22'!$C$5:$J$39,8,0),"") -> 0 | N17: =IFERROR(M17/L17,"") | O17: =IFERROR(VLOOKUP(D17,'ASE Target (Spares), FY 21-22'!$C$5:$K$39,9,0),"") -> 0 | Q17: =IFERROR(P17/O17,"") | R17: =IFERROR(VLOOKUP(D17,'ASE Target (Spares), FY 21-22'!$C$5:$L$39,10,0),"") -> 0 | T17: =IFERROR(S17/R17,"") | U17: =IFERROR(VLOOKUP(D17,'ASE Target (Spares), FY 21-22'!$C$5:$M$39,11,0),"") -> 0 | W17: =IFERROR(V17/U17,"") | X17: =IFERROR(VLOOKUP(D17,'ASE Target (Spares), FY 21-22'!$C$5:$N$39,12,0),"") -> 0 | Z17: =IFERROR(Y17/X17,"") | AA17: =IFERROR(VLOOKUP(D17,'ASE Target (Spares), FY 21-22'!$C$5:$O$39,13,0),"") -> 800000 | AC17: =IFERROR(AB17/AA17,"") -> 0 | AD17: =IFERROR(VLOOKUP(D17,'ASE Target (Spares), FY 21-22'!$C$5:$P$39,14,0),"") -> 800000 | AF17: =IFERROR(AE17/AD17,"") -> 0 | AG17: =IFERROR(VLOOKUP(D17,'ASE Target (Spares), FY 21-22'!$C$5:$Q$39,15,0),"") -> 500000 | AI17: =IFERROR(AH17/AG17,"") -> 0 | AJ17: =IFERROR(VLOOKUP(D17,'ASE Target (Spares), FY 21-22'!$C$5:$R$39,16,0),"") -> 500000 | AL17: =IFERROR(AK17/AJ17,"") -> 0 | AM17: =IFERROR(VLOOKUP(D17,'ASE Target (Spares), FY 21-22'!$C$5:$S$39,17,0),"") -> 500000 | AO17: =IFERROR(AN17/AM17,"") -> 0 | AP17: =IFERROR(F17+I17+L17+O17+R17+U17+X17+AA17+AD17+AG17+AJ17+AM17,"") -> 3600000 | AQ17: =IFERROR(G17+J17+M17+P17+S17+V17+Y17+AB17+AE17+AH17+AK17+AN17,"") -> 747948 | AR17: =IFERROR(AQ17/AP17,"") -> 0.20776333
B18: ='ASE Target (Spares), FY 21-22'!A17 -> 12 | C18: =IF('ASE Target (Spares), FY 21-22'!B17=0,"",'ASE Target (Spares), FY 21-22'!B17) -> DSL-DHK | D18: =IF('ASE Target (Spares), FY 21-22'!C17=0,"",'ASE Target (Spares), FY 21-22'!C17) -> Md. Rakibul Islam | E18: =IF('ASE Target (Spares), FY 21-22'!D17=0,"",'ASE Target (Spares), FY 21-22'!D17) -> 5690 | F18: =IFERROR(VLOOKUP(D18,'ASE Target (Spares), FY 21-22'!$C$5:$H$39,6,0),"") -> 600000 | G18: 542743 | H18: =IFERROR(G18/F18,"") -> 0.90457167 | I18: =IFERROR(VLOOKUP(D18,'ASE Target (Spares), FY 21-22'!$C$5:$I$39,7,0),"") -> 0 | K18: =IFERROR(J18/I18,"") | L18: =IFERROR(VLOOKUP(D18,'ASE Target (Spares), FY 21-22'!$C$5:$J$39,8,0),"") -> 0 | N18: =IFERROR(M18/L18,"") | O18: =IFERROR(VLOOKUP(D18,'ASE Target (Spares), FY 21-22'!$C$5:$K$39,9,0),"") -> 0 | Q18: =IFERROR(P18/O18,"") | R18: =IFERROR(VLOOKUP(D18,'ASE Target (Spares), FY 21-22'!$C$5:$L$39,10,0),"") -> 0 | T18: =IFERROR(S18/R18,"") | U18: =IFERROR(VLOOKUP(D18,'ASE Target (Spares), FY 21-22'!$C$5:$M$39,11,0),"") -> 0 | W18: =IFERROR(V18/U18,"") | X18: =IFERROR(VLOOKUP(D18,'ASE Target (Spares), FY 21-22'!$C$5:$N$39,12,0),"") -> 0 | Z18: =IFERROR(Y18/X18,"") | AA18: =IFERROR(VLOOKUP(D18,'ASE Target (Spares), FY 21-22'!$C$5:$O$39,13,0),"") -> 600000 | AC18: =IFERROR(AB18/AA18,"") -> 0 | AD18: =IFERROR(VLOOKUP(D18,'ASE Target (Spares), FY 21-22'!$C$5:$P$39,14,0),"") -> 600000 | AF18: =IFERROR(AE18/AD18,"") -> 0 | AG18: =IFERROR(VLOOKUP(D18,'ASE Target (Spares), FY 21-22'!$C$5:$Q$39,15,0),"") -> 600000 | AI18: =IFERROR(AH18/AG18,"") -> 0 | AJ18: =IFERROR(VLOOKUP(D18,'ASE Target (Spares), FY 21-22'!$C$5:$R$39,16,0),"") -> 600000 | AL18: =IFERROR(AK18/AJ18,"") -> 0 | AM18: =IFERROR(VLOOKUP(D18,'ASE Target (Spares), FY 21-22'!$C$5:$S$39,17,0),"") -> 600000 | AO18: =IFERROR(AN18/AM18,"") -> 0 | AP18: =IFERROR(F18+I18+L18+O18+R18+U18+X18+AA18+AD18+AG18+AJ18+AM18,"") -> 3600000 | AQ18: =IFERROR(G18+J18+M18+P18+S18+V18+Y18+AB18+AE18+AH18+AK18+AN18,"") -> 542743 | AR18: =IFERROR(AQ18/AP18,"") -> 0.15076194
B19: ='ASE Target (Spares), FY 21-22'!A18 -> 13 | C19: =IF('ASE Target (Spares), FY 21-22'!B18=0,"",'ASE Target (Spares), FY 21-22'!B18) -> DSL-DHK | D19: =IF('ASE Target (Spares), FY 21-22'!C18=0,"",'ASE Target (Spares), FY 21-22'!C18) -> Ohid Hasan Saikat | E19: =IF('ASE Target (Spares), FY 21-22'!D18=0,"",'ASE Target (Spares), FY 21-22'!D18) -> 5691 | F19: =IFERROR(VLOOKUP(D19,'ASE Target (Spares), FY 21-22'!$C$5:$H$39,6,0),"") -> 300000 | H19: =IFERROR(G19/F19,"") -> 0 | I19: =IFERROR(VLOOKUP(D19,'ASE Target (Spares), FY 21-22'!$C$5:$I$39,7,0),"") -> 0 | K19: =IFERROR(J19/I19,"") | L19: =IFERROR(VLOOKUP(D19,'ASE Target (Spares), FY 21-22'!$C$5:$J$39,8,0),"") -> 0 | N19: =IFERROR(M19/L19,"") | O19: =IFERROR(VLOOKUP(D19,'ASE Target (Spares), FY 21-22'!$C$5:$K$39,9,0),"") -> 0 | Q19: =IFERROR(P19/O19,"") | R19: =IFERROR(VLOOKUP(D19,'ASE Target (Spares), FY 21-22'!$C$5:$L$39,10,0),"") -> 0 | T19: =IFERROR(S19/R19,"") | U19: =IFERROR(VLOOKUP(D19,'ASE Target (Spares), FY 21-22'!$C$5:$M$39,11,0),"") -> 0 | W19: =IFERROR(V19/U19,"") | X19: =IFERROR(VLOOKUP(D19,'ASE Target (Spares), FY 21-22'!$C$5:$N$39,12,0),"") -> 0 | Z19: =IFERROR(Y19/X19,"") | AA19: =IFERROR(VLOOKUP(D19,'ASE Target (Spares), FY 21-22'!$C$5:$O$39,13,0),"") -> 300000 | AC19: =IFERROR(AB19/AA19,"") -> 0 | AD19: =IFERROR(VLOOKUP(D19,'ASE Target (Spares), FY 21-22'!$C$5:$P$39,14,0),"") -> 400000 | AF19: =IFERROR(AE19/AD19,"") -> 0 | AG19: =IFERROR(VLOOKUP(D19,'ASE Target (Spares), FY 21-22'!$C$5:$Q$39,15,0),"") -> 300000 | AI19: =IFERROR(AH19/AG19,"") -> 0 | AJ19: =IFERROR(VLOOKUP(D19,'ASE Target (Spares), FY 21-22'!$C$5:$R$39,16,0),"") -> 300000 | AL19: =IFERROR(AK19/AJ19,"") -> 0 | AM19: =IFERROR(VLOOKUP(D19,'ASE Target (Spares), FY 21-22'!$C$5:$S$39,17,0),"") -> 300000 | AO19: =IFERROR(AN19/AM19,"") -> 0 | AP19: =IFERROR(F19+I19+L19+O19+R19+U19+X19+AA19+AD19+AG19+AJ19+AM19,"") -> 1900000 | AQ19: =IFERROR(G19+J19+M19+P19+S19+V19+Y19+AB19+AE19+AH19+AK19+AN19,"") -> 0 | AR19: =IFERROR(AQ19/AP19,"") -> 0
B20: ='ASE Target (Spares), FY 21-22'!A19 -> 14 | C20: =IF('ASE Target (Spares), FY 21-22'!B19=0,"",'ASE Target (Spares), FY 21-22'!B19) -> DSL-DHK | D20: =IF('ASE Target (Spares), FY 21-22'!C19=0,"",'ASE Target (Spares), FY 21-22'!C19) -> Abdullah Al Mahmud | E20: =IF('ASE Target (Spares), FY 21-22'!D19=0,"",'ASE Target (Spares), FY 21-22'!D19) -> 5692 | F20: =IFERROR(VLOOKUP(D20,'ASE Target (Spares), FY 21-22'!$C$5:$H$39,6,0),"") -> 400000 | H20: =IFERROR(G20/F20,"") -> 0 | I20: =IFERROR(VLOOKUP(D20,'ASE Target (Spares), FY 21-22'!$C$5:$I$39,7,0),"") -> 0 | K20: =IFERROR(J20/I20,"") | L20: =IFERROR(VLOOKUP(D20,'ASE Target (Spares), FY 21-22'!$C$5:$J$39,8,0),"") -> 0 | N20: =IFERROR(M20/L20,"") | O20: =IFERROR(VLOOKUP(D20,'ASE Target (Spares), FY 21-22'!$C$5:$K$39,9,0),"") -> 0 | Q20: =IFERROR(P20/O20,"") | R20: =IFERROR(VLOOKUP(D20,'ASE Target (Spares), FY 21-22'!$C$5:$L$39,10,0),"") -> 0 | T20: =IFERROR(S20/R20,"") | U20: =IFERROR(VLOOKUP(D20,'ASE Target (Spares), FY 21-22'!$C$5:$M$39,11,0),"") -> 0 | W20: =IFERROR(V20/U20,"") | X20: =IFERROR(VLOOKUP(D20,'ASE Target (Spares), FY 21-22'!$C$5:$N$39,12,0),"") -> 0 | Z20: =IFERROR(Y20/X20,"") | AA20: =IFERROR(VLOOKUP(D20,'ASE Target (Spares), FY 21-22'!$C$5:$O$39,13,0),"") -> 700000 | AC20: =IFERROR(AB20/AA20,"") -> 0 | AD20: =IFERROR(VLOOKUP(D20,'ASE Target (Spares), FY 21-22'!$C$5:$P$39,14,0),"") -> 400000 | AF20: =IFERROR(AE20/AD20,"") -> 0 | AG20: =IFERROR(VLOOKUP(D20,'ASE Target (Spares), FY 21-22'!$C$5:$Q$39,15,0),"") -> 400000 | AI20: =IFERROR(AH20/AG20,"") -> 0 | AJ20: =IFERROR(VLOOKUP(D20,'ASE Target (Spares), FY 21-22'!$C$5:$R$39,16,0),"") -> 400000 | AL20: =IFERROR(AK20/AJ20,"") -> 0 | AM20: =IFERROR(VLOOKUP(D20,'ASE Target (Spares), FY 21-22'!$C$5:$S$39,17,0),"") -> 400000 | AO20: =IFERROR(AN20/AM20,"") -> 0 | AP20: =IFERROR(F20+I20+L20+O20+R20+U20+X20+AA20+AD20+AG20+AJ20+AM20,"") -> 2700000 | AQ20: =IFERROR(G20+J20+M20+P20+S20+V20+Y20+AB20+AE20+AH20+AK20+AN20,"") -> 0 | AR20: =IFERROR(AQ20/AP20,"") -> 0
B21: ='ASE Target (Spares), FY 21-22'!A20 -> 15 | C21: =IF('ASE Target (Spares), FY 21-22'!B20=0,"",'ASE Target (Spares), FY 21-22'!B20) -> DSL-DHK | D21: =IF('ASE Target (Spares), FY 21-22'!C20=0,"",'ASE Target (Spares), FY 21-22'!C20) -> Apurba Kumar Gain | E21: =IF('ASE Target (Spares), FY 21-22'!D20=0,"",'ASE Target (Spares), FY 21-22'!D20) -> 5927 | F21: =IFERROR(VLOOKUP(D21,'ASE Target (Spares), FY 21-22'!$C$5:$H$39,6,0),"") -> 230000 | G21: 80890 | H21: =IFERROR(G21/F21,"") -> 0.35169565 | I21: =IFERROR(VLOOKUP(D21,'ASE Target (Spares), FY 21-22'!$C$5:$I$39,7,0),"") -> 0 | K21: =IFERROR(J21/I21,"") | L21: =IFERROR(VLOOKUP(D21,'ASE Target (Spares), FY 21-22'!$C$5:$J$39,8,0),"") -> 0 | N21: =IFERROR(M21/L21,"") | O21: =IFERROR(VLOOKUP(D21,'ASE Target (Spares), FY 21-22'!$C$5:$K$39,9,0),"") -> 0 | Q21: =IFERROR(P21/O21,"") | R21: =IFERROR(VLOOKUP(D21,'ASE Target (Spares), FY 21-22'!$C$5:$L$39,10,0),"") -> 0 | T21: =IFERROR(S21/R21,"") | U21: =IFERROR(VLOOKUP(D21,'ASE Target (Spares), FY 21-22'!$C$5:$M$39,11,0),"") -> 0 | W21: =IFERROR(V21/U21,"") | X21: =IFERROR(VLOOKUP(D21,'ASE Target (Spares), FY 21-22'!$C$5:$N$39,12,0),"") -> 0 | Z21: =IFERROR(Y21/X21,"") | AA21: =IFERROR(VLOOKUP(D21,'ASE Target (Spares), FY 21-22'!$C$5:$O$39,13,0),"") -> 0 | AC21: =IFERROR(AB21/AA21,"") | AD21: =IFERROR(VLOOKUP(D21,'ASE Target (Spares), FY 21-22'!$C$5:$P$39,14,0),"") -> 230000 | AF21: =IFERROR(AE21/AD21,"") -> 0 | AG21: =IFERROR(VLOOKUP(D21,'ASE Target (Spares), FY 21-22'!$C$5:$Q$39,15,0),"") -> 230000 | AI21: =IFERROR(AH21/AG21,"") -> 0 | AJ21: =IFERROR(VLOOKUP(D21,'ASE Target (Spares), FY 21-22'!$C$5:$R$39,16,0),"") -> 230000 | AL21: =IFERROR(AK21/AJ21,"") -> 0 | AM21: =IFERROR(VLOOKUP(D21,'ASE Target (Spares), FY 21-22'!$C$5:$S$39,17,0),"") -> 230000 | AO21: =IFERROR(AN21/AM21,"") -> 0 | AP21: =IFERROR(F21+I21+L21+O21+R21+U21+X21+AA21+AD21+AG21+AJ21+AM21,"") -> 1150000 | AQ21: =IFERROR(G21+J21+M21+P21+S21+V21+Y21+AB21+AE21+AH21+AK21+AN21,"") -> 80890 | AR21: =IFERROR(AQ21/AP21,"") -> 0.07033913
B22: ='ASE Target (Spares), FY 21-22'!A21 -> 16 | C22: =IF('ASE Target (Spares), FY 21-22'!B21=0,"",'ASE Target (Spares), FY 21-22'!B21) -> DSL-DHK | D22: =IF('ASE Target (Spares), FY 21-22'!C21=0,"",'ASE Target (Spares), FY 21-22'!C21) -> Amirul Islam | E22: =IF('ASE Target (Spares), FY 21-22'!D21=0,"",'ASE Target (Spares), FY 21-22'!D21) -> 5928 | F22: =IFERROR(VLOOKUP(D22,'ASE Target (Spares), FY 21-22'!$C$5:$H$39,6,0),"") -> 250000 | H22: =IFERROR(G22/F22,"") -> 0 | I22: =IFERROR(VLOOKUP(D22,'ASE Target (Spares), FY 21-22'!$C$5:$I$39,7,0),"") -> 0 | K22: =IFERROR(J22/I22,"") | L22: =IFERROR(VLOOKUP(D22,'ASE Target (Spares), FY 21-22'!$C$5:$J$39,8,0),"") -> 0 | N22: =IFERROR(M22/L22,"") | O22: =IFERROR(VLOOKUP(D22,'ASE Target (Spares), FY 21-22'!$C$5:$K$39,9,0),"") -> 0 | Q22: =IFERROR(P22/O22,"") | R22: =IFERROR(VLOOKUP(D22,'ASE Target (Spares), FY 21-22'!$C$5:$L$39,10,0),"") -> 0 | T22: =IFERROR(S22/R22,"") | U22: =IFERROR(VLOOKUP(D22,'ASE Target (Spares), FY 21-22'!$C$5:$M$39,11,0),"") -> 0 | W22: =IFERROR(V22/U22,"") | X22: =IFERROR(VLOOKUP(D22,'ASE Target (Spares), FY 21-22'!$C$5:$N$39,12,0),"") -> 0 | Z22: =IFERROR(Y22/X22,"") | AA22: =IFERROR(VLOOKUP(D22,'ASE Target (Spares), FY 21-22'!$C$5:$O$39,13,0),"") -> 0 | AC22: =IFERROR(AB22/AA22,"") | AD22: =IFERROR(VLOOKUP(D22,'ASE Target (Spares), FY 21-22'!$C$5:$P$39,14,0),"") -> 250000 | AF22: =IFERROR(AE22/AD22,"") -> 0 | AG22: =IFERROR(VLOOKUP(D22,'ASE Target (Spares), FY 21-22'!$C$5:$Q$39,15,0),"") -> 250000 | AI22: =IFERROR(AH22/AG22,"") -> 0 | AJ22: =IFERROR(VLOOKUP(D22,'ASE Target (Spares), FY 21-22'!$C$5:$R$39,16,0),"") -> 250000 | AL22: =IFERROR(AK22/AJ22,"") -> 0 | AM22: =IFERROR(VLOOKUP(D22,'ASE Target (Spares), FY 21-22'!$C$5:$S$39,17,0),"") -> 250000 | AO22: =IFERROR(AN22/AM22,"") -> 0 | AP22: =IFERROR(F22+I22+L22+O22+R22+U22+X22+AA22+AD22+AG22+AJ22+AM22,"") -> 1250000 | AQ22: =IFERROR(G22+J22+M22+P22+S22+V22+Y22+AB22+AE22+AH22+AK22+AN22,"") -> 0 | AR22: =IFERROR(AQ22/AP22,"") -> 0
B23: ='ASE Target (Spares), FY 21-22'!A22 -> 17 | C23: =IF('ASE Target (Spares), FY 21-22'!B22=0,"",'ASE Target (Spares), FY 21-22'!B22) -> DSL-DHK | D23: =IF('ASE Target (Spares), FY 21-22'!C22=0,"",'ASE Target (Spares), FY 21-22'!C22) -> Md. Jafor Ikbal | E23: =IF('ASE Target (Spares), FY 21-22'!D22=0,"",'ASE Target (Spares), FY 21-22'!D22) -> 5929 | F23: =IFERROR(VLOOKUP(D23,'ASE Target (Spares), FY 21-22'!$C$5:$H$39,6,0),"") -> 0 | H23: =IFERROR(G23/F23,"") | I23: =IFERROR(VLOOKUP(D23,'ASE Target (Spares), FY 21-22'!$C$5:$I$39,7,0),"") -> 0 | K23: =IFERROR(J23/I23,"") | L23: =IFERROR(VLOOKUP(D23,'ASE Target (Spares), FY 21-22'!$C$5:$J$39,8,0),"") -> 0 | N23: =IFERROR(M23/L23,"") | O23: =IFERROR(VLOOKUP(D23,'ASE Target (Spares), FY 21-22'!$C$5:$K$39,9,0),"") -> 0 | Q23: =IFERROR(P23/O23,"") | R23: =IFERROR(VLOOKUP(D23,'ASE Target (Spares), FY 21-22'!$C$5:$L$39,10,0),"") -> 0 | T23: =IFERROR(S23/R23,"") | U23: =IFERROR(VLOOKUP(D23,'ASE Target (Spares), FY 21-22'!$C$5:$M$39,11,0),"") -> 0 | W23: =IFERROR(V23/U23,"") | X23: =IFERROR(VLOOKUP(D23,'ASE Target (Spares), FY 21-22'!$C$5:$N$39,12,0),"") -> 0 | Z23: =IFERROR(Y23/X23,"") | AA23: =IFERROR(VLOOKUP(D23,'ASE Target (Spares), FY 21-22'!$C$5:$O$39,13,0),"") -> 0 | AC23: =IFERROR(AB23/AA23,"") | AD23: =IFERROR(VLOOKUP(D23,'ASE Target (Spares), FY 21-22'!$C$5:$P$39,14,0),"") -> 0 | AF23: =IFERROR(AE23/AD23,"") | AG23: =IFERROR(VLOOKUP(D23,'ASE Target (Spares), FY 21-22'!$C$5:$Q$39,15,0),"") -> 0 | AI23: =IFERROR(AH23/AG23,"") | AJ23: =IFERROR(VLOOKUP(D23,'ASE Target (Spares), FY 21-22'!$C$5:$R$39,16,0),"") -> 0 | AL23: =IFERROR(AK23/AJ23,"") | AM23: =IFERROR(VLOOKUP(D23,'ASE Target (Spares), FY 21-22'!$C$5:$S$39,17,0),"") -> 0 | AO23: =IFERROR(AN23/AM23,"") | AP23: =IFERROR(F23+I23+L23+O23+R23+U23+X23+AA23+AD23+AG23+AJ23+AM23,"") -> 0 | AQ23: =IFERROR(G23+J23+M23+P23+S23+V23+Y23+AB23+AE23+AH23+AK23+AN23,"") -> 0 | AR23: =IFERROR(AQ23/AP23,"")
B24: ='ASE Target (Spares), FY 21-22'!A29 -> 18 | C24: =IF('ASE Target (Spares), FY 21-22'!B23=0,"",'ASE Target (Spares), FY 21-22'!B23) -> DSL-DHK | D24: =IF('ASE Target (Spares), FY 21-22'!C23=0,"",'ASE Target (Spares), FY 21-22'!C23) -> Md. Habibur Rahman | E24: =IF('ASE Target (Spares), FY 21-22'!D23=0,"",'ASE Target (Spares), FY 21-22'!D23) -> 6079 | F24: =IFERROR(VLOOKUP(D24,'ASE Target (Spares), FY 21-22'!$C$5:$H$39,6,0),"") -> 250000 | G24: 263694 | H24: =IFERROR(G24/F24,"") -> 1.054776 | I24: =IFERROR(VLOOKUP(D24,'ASE Target (Spares), FY 21-22'!$C$5:$I$39,7,0),"") -> 0 | K24: =IFERROR(J24/I24,"") | L24: =IFERROR(VLOOKUP(D24,'ASE Target (Spares), FY 21-22'!$C$5:$J$39,8,0),"") -> 0 | N24: =IFERROR(M24/L24,"") | O24: =IFERROR(VLOOKUP(D24,'ASE Target (Spares), FY 21-22'!$C$5:$K$39,9,0),"") -> 0 | Q24: =IFERROR(P24/O24,"") | R24: =IFERROR(VLOOKUP(D24,'ASE Target (Spares), FY 21-22'!$C$5:$L$39,10,0),"") -> 0 | T24: =IFERROR(S24/R24,"") | U24: =IFERROR(VLOOKUP(D24,'ASE Target (Spares), FY 21-22'!$C$5:$M$39,11,0),"") -> 0 | W24: =IFERROR(V24/U24,"") | X24: =IFERROR(VLOOKUP(D24,'ASE Target (Spares), FY 21-22'!$C$5:$N$39,12,0),"") -> 0 | Z24: =IFERROR(Y24/X24,"") | AA24: =IFERROR(VLOOKUP(D24,'ASE Target (Spares), FY 21-22'!$C$5:$O$39,13,0),"") -> 0 | AC24: =IFERROR(AB24/AA24,"") | AD24: =IFERROR(VLOOKUP(D24,'ASE Target (Spares), FY 21-22'!$C$5:$P$39,14,0),"") -> 0 | AF24: =IFERROR(AE24/AD24,"") | AG24: =IFERROR(VLOOKUP(D24,'ASE Target (Spares), FY 21-22'!$C$5:$Q$39,15,0),"") -> 0 | AI24: =IFERROR(AH24/AG24,"") | AJ24: =IFERROR(VLOOKUP(D24,'ASE Target (Spares), FY 21-22'!$C$5:$R$39,16,0),"") -> 0 | AL24: =IFERROR(AK24/AJ24,"") | AM24: =IFERROR(VLOOKUP(D24,'ASE Target (Spares), FY 21-22'!$C$5:$S$39,17,0),"") -> 250000 | AO24: =IFERROR(AN24/AM24,"") -> 0 | AP24: =IFERROR(F24+I24+L24+O24+R24+U24+X24+AA24+AD24+AG24+AJ24+AM24,"") -> 500000 | AQ24: =IFERROR(G24+J24+M24+P24+S24+V24+Y24+AB24+AE24+AH24+AK24+AN24,"") -> 263694 | AR24: =IFERROR(AQ24/AP24,"") -> 0.527388
B25: ='ASE Target (Spares), FY 21-22'!A30 -> 19 | C25: =IF('ASE Target (Spares), FY 21-22'!B24=0,"",'ASE Target (Spares), FY 21-22'!B24) -> DSL-DHK | D25: =IF('ASE Target (Spares), FY 21-22'!C24=0,"",'ASE Target (Spares), FY 21-22'!C24) -> Ashikur Rahman | E25: =IF('ASE Target (Spares), FY 21-22'!D24=0,"",'ASE Target (Spares), FY 21-22'!D24) -> 6080 | F25: =IFERROR(VLOOKUP(D25,'ASE Target (Spares), FY 21-22'!$C$5:$H$39,6,0),"") -> 500000 | H25: =IFERROR(G25/F25,"") -> 0 | I25: =IFERROR(VLOOKUP(D25,'ASE Target (Spares), FY 21-22'!$C$5:$I$39,7,0),"") -> 0 | K25: =IFERROR(J25/I25,"") | L25: =IFERROR(VLOOKUP(D25,'ASE Target (Spares), FY 21-22'!$C$5:$J$39,8,0),"") -> 0 | N25: =IFERROR(M25/L25,"") | O25: =IFERROR(VLOOKUP(D25,'ASE Target (Spares), FY 21-22'!$C$5:$K$39,9,0),"") -> 0 | Q25: =IFERROR(P25/O25,"") | R25: =IFERROR(VLOOKUP(D25,'ASE Target (Spares), FY 21-22'!$C$5:$L$39,10,0),"") -> 0 | T25: =IFERROR(S25/R25,"") | U25: =IFERROR(VLOOKUP(D25,'ASE Target (Spares), FY 21-22'!$C$5:$M$39,11,0),"") -> 0 | W25: =IFERROR(V25/U25,"") | X25: =IFERROR(VLOOKUP(D25,'ASE Target (Spares), FY 21-22'!$C$5:$N$39,12,0),"") -> 0 | Z25: =IFERROR(Y25/X25,"") | AA25: =IFERROR(VLOOKUP(D25,'ASE Target (Spares), FY 21-22'!$C$5:$O$39,13,0),"") -> 0 | AC25: =IFERROR(AB25/AA25,"") | AD25: =IFERROR(VLOOKUP(D25,'ASE Target (Spares), FY 21-22'!$C$5:$P$39,14,0),"") -> 0 | AF25: =IFERROR(AE25/AD25,"") | AG25: =IFERROR(VLOOKUP(D25,'ASE Target (Spares), FY 21-22'!$C$5:$Q$39,15,0),"") -> 0 | AI25: =IFERROR(AH25/AG25,"") | AJ25: =IFERROR(VLOOKUP(D25,'ASE Target (Spares), FY 21-22'!$C$5:$R$39,16,0),"") -> 0 | AL25: =IFERROR(AK25/AJ25,"") | AM25: =IFERROR(VLOOKUP(D25,'ASE Target (Spares), FY 21-22'!$C$5:$S$39,17,0),"") -> 500000 | AO25: =IFERROR(AN25/AM25,"") -> 0 | AP25: =IFERROR(F25+I25+L25+O25+R25+U25+X25+AA25+AD25+AG25+AJ25+AM25,"") -> 1000000 | AQ25: =IFERROR(G25+J25+M25+P25+S25+V25+Y25+AB25+AE25+AH25+AK25+AN25,"") -> 0 | AR25: =IFERROR(AQ25/AP25,"") -> 0
B26: ='ASE Target (Spares), FY 21-22'!A31 -> 20 | C26: =IF('ASE Target (Spares), FY 21-22'!B25=0,"",'ASE Target (Spares), FY 21-22'!B25) -> DSL-DHK | D26: =IF('ASE Target (Spares), FY 21-22'!C25=0,"",'ASE Target (Spares), FY 21-22'!C25) -> Md. Sujon Hossain | E26: =IF('ASE Target (Spares), FY 21-22'!D25=0,"",'ASE Target (Spares), FY 21-22'!D25) -> 6078 | F26: =IFERROR(VLOOKUP(D26,'ASE Target (Spares), FY 21-22'!$C$5:$H$39,6,0),"") -> 600000 | G26: 290128 | H26: =IFERROR(G26/F26,"") -> 0.48354667 | I26: =IFERROR(VLOOKUP(D26,'ASE Target (Spares), FY 21-22'!$C$5:$I$39,7,0),"") -> 0 | K26: =IFERROR(J26/I26,"") | L26: =IFERROR(VLOOKUP(D26,'ASE Target (Spares), FY 21-22'!$C$5:$J$39,8,0),"") -> 0 | N26: =IFERROR(M26/L26,"") | O26: =IFERROR(VLOOKUP(D26,'ASE Target (Spares), FY 21-22'!$C$5:$K$39,9,0),"") -> 0 | Q26: =IFERROR(P26/O26,"") | R26: =IFERROR(VLOOKUP(D26,'ASE Target (Spares), FY 21-22'!$C$5:$L$39,10,0),"") -> 0 | T26: =IFERROR(S26/R26,"") | U26: =IFERROR(VLOOKUP(D26,'ASE Target (Spares), FY 21-22'!$C$5:$M$39,11,0),"") -> 0 | W26: =IFERROR(V26/U26,"") | X26: =IFERROR(VLOOKUP(D26,'ASE Target (Spares), FY 21-22'!$C$5:$N$39,12,0),"") -> 0 | Z26: =IFERROR(Y26/X26,"") | AA26: =IFERROR(VLOOKUP(D26,'ASE Target (Spares), FY 21-22'!$C$5:$O$39,13,0),"") -> 0 | AC26: =IFERROR(AB26/AA26,"") | AD26: =IFERROR(VLOOKUP(D26,'ASE Target (Spares), FY 21-22'!$C$5:$P$39,14,0),"") -> 0 | AF26: =IFERROR(AE26/AD26,"") | AG26: =IFERROR(VLOOKUP(D26,'ASE Target (Spares), FY 21-22'!$C$5:$Q$39,15,0),"") -> 0 | AI26: =IFERROR(AH26/AG26,"") | AJ26: =IFERROR(VLOOKUP(D26,'ASE Target (Spares), FY 21-22'!$C$5:$R$39,16,0),"") -> 0 | AL26: =IFERROR(AK26/AJ26,"") | AM26: =IFERROR(VLOOKUP(D26,'ASE Target (Spares), FY 21-22'!$C$5:$S$39,17,0),"") -> 600000 | AO26: =IFERROR(AN26/AM26,"") -> 0 | AP26: =IFERROR(F26+I26+L26+O26+R26+U26+X26+AA26+AD26+AG26+AJ26+AM26,"") -> 1200000 | AQ26: =IFERROR(G26+J26+M26+P26+S26+V26+Y26+AB26+AE26+AH26+AK26+AN26,"") -> 290128 | AR26: =IFERROR(AQ26/AP26,"") -> 0.24177333
B27: ='ASE Target (Spares), FY 21-22'!A32 -> 21 | C27: =IF('ASE Target (Spares), FY 21-22'!B26=0,"",'ASE Target (Spares), FY 21-22'!B26) -> DSL-DHK | D27: =IF('ASE Target (Spares), FY 21-22'!C26=0,"",'ASE Target (Spares), FY 21-22'!C26) -> Md Jiaur Rahman | E27: =IF('ASE Target (Spares), FY 21-22'!D26=0,"",'ASE Target (Spares), FY 21-22'!D26) -> 0522 | F27: =IFERROR(VLOOKUP(D27,'ASE Target (Spares), FY 21-22'!$C$5:$H$39,6,0),"") -> 900000 | H27: =IFERROR(G27/F27,"") -> 0 | I27: =IFERROR(VLOOKUP(D27,'ASE Target (Spares), FY 21-22'!$C$5:$I$39,7,0),"") -> 0 | K27: =IFERROR(J27/I27,"") | L27: =IFERROR(VLOOKUP(D27,'ASE Target (Spares), FY 21-22'!$C$5:$J$39,8,0),"") -> 0 | N27: =IFERROR(M27/L27,"") | O27: =IFERROR(VLOOKUP(D27,'ASE Target (Spares), FY 21-22'!$C$5:$K$39,9,0),"") -> 0 | Q27: =IFERROR(P27/O27,"") | R27: =IFERROR(VLOOKUP(D27,'ASE Target (Spares), FY 21-22'!$C$5:$L$39,10,0),"") -> 0 | T27: =IFERROR(S27/R27,"") | U27: =IFERROR(VLOOKUP(D27,'ASE Target (Spares), FY 21-22'!$C$5:$M$39,11,0),"") -> 0 | W27: =IFERROR(V27/U27,"") | X27: =IFERROR(VLOOKUP(D27,'ASE Target (Spares), FY 21-22'!$C$5:$N$39,12,0),"") -> 0 | Z27: =IFERROR(Y27/X27,"") | AA27: =IFERROR(VLOOKUP(D27,'ASE Target (Spares), FY 21-22'!$C$5:$O$39,13,0),"") -> 0 | AC27: =IFERROR(AB27/AA27,"") | AD27: =IFERROR(VLOOKUP(D27,'ASE Target (Spares), FY 21-22'!$C$5:$P$39,14,0),"") -> 850000 | AF27: =IFERROR(AE27/AD27,"") -> 0 | AG27: =IFERROR(VLOOKUP(D27,'ASE Target (Spares), FY 21-22'!$C$5:$Q$39,15,0),"") -> 850000 | AI27: =IFERROR(AH27/AG27,"") -> 0 | AJ27: =IFERROR(VLOOKUP(D27,'ASE Target (Spares), FY 21-22'!$C$5:$R$39,16,0),"") -> 850000 | AL27: =IFERROR(AK27/AJ27,"") -> 0 | AM27: =IFERROR(VLOOKUP(D27,'ASE Target (Spares), FY 21-22'!$C$5:$S$39,17,0),"") -> 900000 | AO27: =IFERROR(AN27/AM27,"") -> 0 | AP27: =IFERROR(F27+I27+L27+O27+R27+U27+X27+AA27+AD27+AG27+AJ27+AM27,"") -> 4350000 | AQ27: =IFERROR(G27+J27+M27+P27+S27+V27+Y27+AB27+AE27+AH27+AK27+AN27,"") -> 0 | AR27: =IFERROR(AQ27/AP27,"") -> 0
B28: ='ASE Target (Spares), FY 21-22'!A36 -> 0 | C28: =IF('ASE Target (Spares), FY 21-22'!B27=0,"",'ASE Target (Spares), FY 21-22'!B27) | D28: =IF('ASE Target (Spares), FY 21-22'!C27=0,"",'ASE Target (Spares), FY 21-22'!C27) -> New-2 | E28: =IF('ASE Target (Spares), FY 21-22'!D27=0,"",'ASE Target (Spares), FY 21-22'!D27) | F28: =IFERROR(VLOOKUP(D28,'ASE Target (Spares), FY 21-22'!$C$5:$H$39,6,0),"") -> 0 | H28: =IFERROR(G28/F28,"") | I28: =IFERROR(VLOOKUP(D28,'ASE Target (Spares), FY 21-22'!$C$5:$I$39,7,0),"") -> 0 | K28: =IFERROR(J28/I28,"") | L28: =IFERROR(VLOOKUP(D28,'ASE Target (Spares), FY 21-22'!$C$5:$J$39,8,0),"") -> 0 | N28: =IFERROR(M28/L28,"") | O28: =IFERROR(VLOOKUP(D28,'ASE Target (Spares), FY 21-22'!$C$5:$K$39,9,0),"") -> 0 | Q28: =IFERROR(P28/O28,"") | R28: =IFERROR(VLOOKUP(D28,'ASE Target (Spares), FY 21-22'!$C$5:$L$39,10,0),"") -> 0 | T28: =IFERROR(S28/R28,"") | U28: =IFERROR(VLOOKUP(D28,'ASE Target (Spares), FY 21-22'!$C$5:$M$39,11,0),"") -> 0 | W28: =IFERROR(V28/U28,"") | X28: =IFERROR(VLOOKUP(D28,'ASE Target (Spares), FY 21-22'!$C$5:$N$39,12,0),"") -> 0 | Z28: =IFERROR(Y28/X28,"") | AA28: =IFERROR(VLOOKUP(D28,'ASE Target (Spares), FY 21-22'!$C$5:$O$39,13,0),"") -> 0 | AC28: =IFERROR(AB28/AA28,"") | AD28: =IFERROR(VLOOKUP(D28,'ASE Target (Spares), FY 21-22'!$C$5:$P$39,14,0),"") -> 0 | AF28: =IFERROR(AE28/AD28,"") | AG28: =IFERROR(VLOOKUP(D28,'ASE Target (Spares), FY 21-22'!$C$5:$Q$39,15,0),"") -> 0 | AI28: =IFERROR(AH28/AG28,"") | AJ28: =IFERROR(VLOOKUP(D28,'ASE Target (Spares), FY 21-22'!$C$5:$R$39,16,0),"") -> 0 | AL28: =IFERROR(AK28/AJ28,"") | AM28: =IFERROR(VLOOKUP(D28,'ASE Target (Spares), FY 21-22'!$C$5:$S$39,17,0),"") -> 0 | AO28: =IFERROR(AN28/AM28,"") | AP28: =IFERROR(F28+I28+L28+O28+R28+U28+X28+AA28+AD28+AG28+AJ28+AM28,"") -> 0 | AQ28: =IFERROR(G28+J28+M28+P28+S28+V28+Y28+AB28+AE28+AH28+AK28+AN28,"") -> 0 | AR28: =IFERROR(AQ28/AP28,"")
